<?xml version="1.0" ?>
<robot name="robot_description">

<material name="white">
        <color rgba="1 1 1 1" />
    </material>

    <material name="orange">
        <color rgba="1 0.3 0.1 1"/>
    </material>

    <material name="blue">
        <color rgba="0.2 0.2 1 1"/>
    </material>

    <material name="green">
        <color rgba="0.2 1 0.2 1"/>
    </material>

    <material name="black">
        <color rgba="0 0 0 1"/>
    </material>

    <!-- BASE LINK -->

    <link name="base_link">
        
    </link>

    

    <!-- CHASSIS LINK -->

    <joint name="chassis_joint" type="fixed">
        <parent link="base_link"/>
        <child link="chassis"/>
        <origin xyz="-0.1150 0 0"/>
    </joint>

    <link name="chassis">
        <visual>
            <origin xyz="0.2794 0 0.3485"/>
            <geometry>
                <box size="0.5588 0.5334 0.1524"/>
            </geometry>
            <material name="white"/>
        </visual>
        <collision>
            <origin xyz="0.2286 0 0.66507"/>
            <geometry>
                <box size="0.889 0.889 1.524"/>
            </geometry>
        </collision>
    </link>

    <!-- ELECTRONICS BOX LINK -->

    <joint name="chassis_elec_joint" type="fixed">
        <parent link="chassis"/>
        <child link="elec_box"/>
        <origin xyz="0 0 0.4247"/>
    </joint>

    <link name="elec_box">
        <visual>
            <origin xyz="0.13335 0 0.0921"/>
            <geometry>
                <box size="0.2667 0.5334 0.18415"/>
            </geometry>
            <material name="white"/>
        </visual>
        <collision>
            <origin xyz="0.13335 0 0.0921"/>
            <geometry>
                <box size="0.2667 0.5334 0.18415"/>
            </geometry>
        </collision>
    </link>

    <!-- CHASSIS BACK LEFT LEG LINK -->

    <joint name="chassis_back_left_leg_joint" type="fixed">
        <parent link="chassis"/>
        <child link="chassis_back_left_leg"/>
        <origin xyz="0.1150 0.19685 0"/>
    </joint>

    <link name="chassis_back_left_leg">
        <visual>
            <origin xyz="-0.0277 0 0.1167"/>
            <geometry>
                <box size="0.1746 0.1397 0.3112"/>
            </geometry>
            <material name="white"/>
        </visual>
        <collision>
            <origin xyz="-0.0277 0 0.1167"/>
            <geometry>
                <box size="0.1746 0.1397 0.3112"/>
            </geometry>
        </collision>
    </link>

    <!-- CHASSIS BACK RIGHT LEG LINK -->

    <joint name="chassis_back_right_leg_joint" type="fixed">
        <parent link="chassis"/>
        <child link="chassis_back_right_leg"/>
        <origin xyz="0.1150 -0.19685 0"/>
    </joint>

    <link name="chassis_back_right_leg">
        <visual>
            <origin xyz="-0.0277 0 0.1167"/>
            <geometry>
                <box size="0.1746 0.1397 0.3112"/>
            </geometry>
            <material name="white"/>
        </visual>
        <collision>
            <origin xyz="-0.0277 0 0.1167"/>
            <geometry>
                <box size="0.1746 0.1397 0.3112"/>
            </geometry>
        </collision>
    </link>

    <!-- LEFT CHASSIS FRONT LEG LINK -->
    <joint name="chassis_front_left_leg_joint" type="fixed">
        <parent link="chassis"/>
        <child link="chassis_front_left_leg"/>
        <origin xyz="0.4953 0.19685 0.127"/>
    </joint>

    <link name="chassis_front_left_leg">
        <visual>
            <origin xyz="0 0 0.0727"/>
            <geometry>
                <box size="0.127 0.1397 0.1453"/>
            </geometry>
            <material name="white"/>
        </visual>
        <collision>
            <origin xyz="0 0 0.0727"/>
            <geometry>
                <box size="0.127 0.1397 0.1453"/>
            </geometry>
        </collision>
    </link>

    <!-- RIGHT CHASSIS FRONT LEG LINK -->
    <joint name="chassis_front_right_leg_joint" type="fixed">
        <parent link="chassis"/>
        <child link="chassis_front_right_leg"/>
        <origin xyz="0.4953 -0.19685 0.127"/>
    </joint>

    <link name="chassis_front_right_leg">
        <visual>
            <origin xyz="0 0 0.0727"/>
            <geometry>
                <box size="0.127 0.1397 0.1453"/>
            </geometry>
            <material name="white"/>
        </visual>
        <collision>
            <origin xyz="0 0 0.0727"/>
            <geometry>
                <box size="0.127 0.1397 0.1453"/>
            </geometry>
        </collision>
    </link>

    <!-- BACK LEFT WHEEL LINK -->

    <joint name="back_left_wheel_joint" type="continuous">
        <parent link="chassis_back_left_leg"/>
        <child link="back_left_wheel"/>
        <origin xyz="0 0.1143 0" rpy="-1.57 0 0" />
        <axis xyz="0 0 1"/>
    </joint>

    <link name="back_left_wheel">
        <visual>
            <geometry>
                <cylinder radius="0.127" length="0.0889"/>
            </geometry>
            <material name="blue"/>
        </visual>
        <collision>
            <geometry>
                <cylinder radius="0.127" length="0.0889"/>
            </geometry>
        </collision>
    </link>

    <!-- BACK RIGHT WHEEL LINK -->

    <joint name="back_right_wheel_joint" type="continuous">
        <parent link="chassis_back_right_leg"/>
        <child link="back_right_wheel"/>
        <origin xyz="0 -0.1143 0" rpy="-1.57 0 0" />
        <axis xyz="0 0 -1"/>
    </joint>

    <link name="back_right_wheel">
        <visual>
            <geometry>
                <cylinder radius="0.127" length="0.0889"/>
            </geometry>
            <material name="blue"/>
        </visual>
        <collision>
            <geometry>
                <cylinder radius="0.127" length="0.0889"/>
            </geometry>
        </collision>
    </link>

     <!-- CASTER FRONT LEFT WHEEL LINK -->

    <joint name="front_left_wheel_joint" type="fixed">
        <parent link="chassis_front_left_leg"/>
        <child link="front_left_wheel"/>
        <origin xyz="0 0 -0.127"/>
    </joint>


    <link name="front_left_wheel">
        <visual>
            <geometry>
                <sphere radius="0.127"/>
            </geometry>
            <material name="blue"/>
        </visual>
        <collision>
            <geometry>
                <sphere radius="0.127"/>
            </geometry>
        </collision>
    </link>

<!-- CASTER FRONT RIGHT WHEEL LINK -->

    <joint name="front_right_wheel_joint" type="fixed">
        <parent link="chassis_front_right_leg"/>
        <child link="front_right_wheel"/>
        <origin xyz="0 0 -0.127"/>
    </joint>


    <link name="front_right_wheel">
        <visual>
            <geometry>
                <sphere radius="0.127"/>
            </geometry>
            <material name="blue"/>
        </visual>
        <collision>
            <geometry>
                <sphere radius="0.127"/>
            </geometry>
        </collision>
    </link>

    <!-- IMU LINK -->
    <joint name="imu_joint" type="fixed">
        <parent link="base_link"/>
        <child link="imu_link"/>
        <origin xyz="0.127 0 0.4247"/>
    </joint>


    <link name="imu_link">
        <visual>
            <origin xyz="0 0 0"/>
            <geometry>
                <box size="0.0254 0.01905 0.00635"/>
            </geometry>
            <material name="orange"/>
        </visual>
        <collision>
            <origin xyz="0 0 0"/>
            <geometry>
                <box size="0.0254 0.01905 0.00635"/>
            </geometry>
        </collision>
    </link>

    <!-- CAMERA LINK -->
    <joint name="camera_joint" type="fixed">
        <parent link="base_link"/>
        <child link="kinect"/>
        <origin xyz="-0.2166 0 1.33015"/>
    </joint>


    <link name="kinect">
        <visual>
            <origin xyz="-0.04445 0 0"/>
            <geometry>
                <box size="0.08255 0.254 0.0762"/>
            </geometry>
            <material name="orange"/>
        </visual>
        <collision>
            <origin xyz="-0.04445 0 0"/>
            <geometry>
                <box size="0.08255 0.254 0.0762"/>
            </geometry>
        </collision>
    </link>

</robot>


